Workbook

Sheet Источник 1
A3: ID | B3: Фамилия | C3: Имя | D3: Должность | E3: Бизнес-юнит | F3: Зарплата | G3: Бонус
A4: 1 | B4: Miller | C4: Jennifer | D4: Senior Manager | E4: B01 | F4: 172000 | G4: 20000
A5: 2 | B5: Rubin | C5: Thomas | D5: Software Engineer | E5: B01 | F5: 82000
A6: 3 | B6: Smith | C6: Peter | D6: Programmer | E6: B01 | F6: 48000 | G6: 1000
A7: 4 | B7: Coulter | C7: Tony | D7: Programmer | E7: B01 | F7: 90000
A8: 5 | B8: Gupta | C8: Rajiv | D8: Manager | E8: B01 | F8: 130000 | G8: 5000
A9: 6 | B9: Williams-Martinez | C9: Belinda | D9: Manager | E9: B01 | F9: 96000
A10: 7 | B10: Niedzwiecki | C10: Edward | D10: Programmer | E10: B01 | F10: 88000
A11: 8 | B11: Wang | C11: Kenny | D11: Consultant | E11: B01 | F11: 38000 | G11: 5000
A12: 9 | B12: Adams | C12: Frank | D12: Programmer | E12: B01 | F12: 46000
A13: 10 | B13: Niedzwiecki | C13: Stephanie | D13: Manager | E13: B01 | F13: 150000 | G13: 10000
A14: 11 | B14: Mallory | C14: Petee | D14: Programmer | E14: B01 | F14: 52000 | G14: 3000
A15: 12 | B15: Messer | C15: Hillary | D15: Software Engineer | E15: B01 | F15: 54000 | G15: 3000
A16: 13 | B16: Fleming | C16: James | D16: Manager | E16: B01 | F16: 100000 | G16: 20000
A17: 20 | B17: Fisher | C17: Charles | D17: Programmer | E17: B01 | F17: 88000
A18: 21 | B18: Johnson | C18: Barbara | D18: Software Analyst | E18: B01 | F18: 106000
A19: 30 | B19: Miller | C19: Jennifer | D19: Consultant | E19: B01 | F19: 72000
A20: 32 | B20: Rubin | C20: Thomas | D20: Software Developer | E20: B01 | F20: 82000
A21: 34 | B21: Smith | C21: Peter | D21: Programmer | E21: B01 | F21: 58000 | G21: 500
A22: 35 | B22: Czarny | C22: Tony | D22: Consultant | E22: B01 | F22: 80000
A23: 33 | B23: Williams-Aikman | C23: Valerie | D23: Manager | E23: B01 | F23: 96000
A24: 36 | B24: Niedzwiecki | C24: Arnold | D24: Software Developer | E24: B01 | F24: 88000
A25: 40 | B25: Martinez | C25: Pedro | D25: Software Engineer | E25: B01 | F25: 48000 | G25: 500
A26: 41 | B26: Adams | C26: Jessica | D26: Software Developer | E26: B01 | F26: 46000
A27: 42 | B27: Niedzwiecki | C27: Meredith | D27: Project Manager | E27: B01 | F27: 120000
A28: 43 | B28: Rokovky | C28: Vladimir | D28: Programmer | E28: B01 | F28: 76000 | G28: 2000
A29: 44 | B29: Mallory | C29: Jan | D29: System Engineer | E29: B01 | F29: 52000
A30: 45 | B30: Messer | C30: Amy | D30: Programmer | E30: B01 | F30: 84000 | G30: 500
A31: 55 | B31: Herbert | C31: Arnold | D31: System Engineer | E31: B01 | F31: 88000
A32: 47 | B32: Martinez | C32: Karine | D32: Software Analyst | E32: B01 | F32: 48000 | G32: 500
A33: 48 | B33: Banister | C33: Jessica | D33: Consultant | E33: B01 | F33: 46000
A34: 65 | B34: Rodes | C34: Meredith | D34: Project Manager | E34: B01 | F34: 120000
A35: 61 | B35: Evans | C35: Jan | D35: Programmer | E35: B01 | F35: 52000 | G35: 5000
A36: 67 | B36: Adamson | C36: James | D36: Project Manager | E36: B01 | F36: 120000 | G36: 5000
A37: 68 | B37: Brown | C37: Charles | D37: Software Developer | E37: B01 | F37: 88000 | G37: 500
A38: 69 | B38: Johnson | C38: Diane | D38: Programmer | E38: B01 | F38: 96000 | G38: 1000
A39: 71 | B39: Horak | C39: Amy | D39: Consultant | E39: B01 | F39: 84000 | G39: 1000
A40: 81 | B40: Horak | C40: Christine | D40: Programmer | E40: B01 | F40: 70000 | G40: 10000
A41: 82 | B41: Gupta | C41: Amlan | D41: Programmer | E41: B01 | F41: 89000 | G41: 1500
A42: 83 | B42: Banister | C42: Gwen | D42: System Engineer | E42: B01 | F42: 46000
...

Sheet Задания 1.1
B2: Сцепить | C2: ВПР | D2: ВПР | E2: Если | L2: СУММЕСЛИ | M2: СУММЕСЛИ | N2: СЧЕТЕСЛИМН
A3: ID | B3: Фамилия + Имя | C3: Должность | D3: Бизнес-юнит | E3: Получил бонус? | K3: Бизнес - юнит | L3: Сумма зарплаты | M3: Сумма бонусов | N3: Количество Бонусов
A4: 1 | B4: =_xlfn.CONCAT('Источник 1'!B4," ",'Источник 1'!C4) -> Miller Jennifer | C4: =VLOOKUP('Источник 1'!A4,'Источник 1'!A4:G235, 4,0) -> Senior Manager | D4: =VLOOKUP('Источник 1'!A4,'Источник 1'!A4:G235,5,0) -> B01 | E4: =IF('Источник 1'!G4>0,"YES","NO") -> YES | K4: B01 | L4: =SUMIF('Источник 1'!E4:F235,'Задания 1.1'!K4,'Источник 1'!F4:F235) -> 5824000 | M4: =SUMIF('Источник 1'!E4:G235, 'Задания 1.1'!K4, 'Источник 1'!G4:G235) -> 106000 | N4: =COUNTIFS(D4:D235,K4,E4:E235,"YES") -> 26
A5: 2 | B5: =_xlfn.CONCAT('Источник 1'!B5," ",'Источник 1'!C5) -> Rubin Thomas | C5: =VLOOKUP('Источник 1'!A5,'Источник 1'!A5:G236, 4,0) -> Software Engineer | D5: =VLOOKUP('Источник 1'!A5,'Источник 1'!A5:G236,5,0) -> B01 | E5: =IF('Источник 1'!G5>0,"YES","NO") -> NO | K5: B92 | L5: =SUMIF('Источник 1'!E4:F235,'Задания 1.1'!K5,'Источник 1'!F4:F235) -> 427000 | M5: =SUMIF('Источник 1'!E5:G236, 'Задания 1.1'!K5, 'Источник 1'!G5:G236) -> 28000 | N5: =COUNTIFS(D5:D236,K5,E5:E236,"YES") -> 4
A6: 3 | B6: =_xlfn.CONCAT('Источник 1'!B6," ",'Источник 1'!C6) -> Smith Peter | C6: =VLOOKUP('Источник 1'!A6,'Источник 1'!A6:G237, 4,0) -> Programmer | D6: =VLOOKUP('Источник 1'!A6,'Источник 1'!A6:G237,5,0) -> B01 | E6: =IF('Источник 1'!G6>0,"YES","NO") -> YES | K6: B77 | L6: =SUMIF('Источник 1'!E5:F236,'Задания 1.1'!K6,'Источник 1'!F5:F236) -> 440000 | M6: =SUMIF('Источник 1'!E6:G237, 'Задания 1.1'!K6, 'Источник 1'!G6:G237) -> 8000 | N6: =COUNTIFS(D6:D237,K6,E6:E237,"YES") -> 4
A7: 4 | B7: =_xlfn.CONCAT('Источник 1'!B7," ",'Источник 1'!C7) -> Coulter Tony | C7: =VLOOKUP('Источник 1'!A7,'Источник 1'!A7:G238, 4,0) -> Programmer | D7: =VLOOKUP('Источник 1'!A7,'Источник 1'!A7:G238,5,0) -> B01 | E7: =IF('Источник 1'!G7>0,"YES","NO") -> YES | K7: B18 | L7: =SUMIF('Источник 1'!E6:F237,'Задания 1.1'!K7,'Источник 1'!F6:F237) -> 306000 | M7: =SUMIF('Источник 1'!E7:G238, 'Задания 1.1'!K7, 'Источник 1'!G7:G238) -> 25000 | N7: =COUNTIFS(D7:D238,K7,E7:E238,"YES") -> 1
A8: 5 | B8: =_xlfn.CONCAT('Источник 1'!B8," ",'Источник 1'!C8) -> Gupta Rajiv | C8: =VLOOKUP('Источник 1'!A8,'Источник 1'!A8:G239, 4,0) -> Manager | D8: =VLOOKUP('Источник 1'!A8,'Источник 1'!A8:G239,5,0) -> B01 | E8: =IF('Источник 1'!G8>0,"YES","NO") -> YES | K8: B19 | L8: =SUMIF('Источник 1'!E7:F238,'Задания 1.1'!K8,'Источник 1'!F7:F238) -> 235000 | M8: =SUMIF('Источник 1'!E8:G239, 'Задания 1.1'!K8, 'Источник 1'!G8:G239) -> 0 | N8: =COUNTIFS(D8:D239,K8,E8:E239,"YES") -> 0
A9: 6 | B9: =_xlfn.CONCAT('Источник 1'!B9," ",'Источник 1'!C9) -> Williams-Martinez Belinda | C9: =VLOOKUP('Источник 1'!A9,'Источник 1'!A9:G240, 4,0) -> Manager | D9: =VLOOKUP('Источник 1'!A9,'Источник 1'!A9:G240,5,0) -> B01 | E9: =IF('Источник 1'!G9>0,"YES","NO") -> NO | K9: B20 | L9: =SUMIF('Источник 1'!E8:F239,'Задания 1.1'!K9,'Источник 1'!F8:F239) -> 202000 | M9: =SUMIF('Источник 1'!E9:G240, 'Задания 1.1'!K9, 'Источник 1'!G9:G240) -> 3000 | N9: =COUNTIFS(D9:D240,K9,E9:E240,"YES") -> 1
A10: 7 | B10: =_xlfn.CONCAT('Источник 1'!B10," ",'Источник 1'!C10) -> Niedzwiecki Edward | C10: =VLOOKUP('Источник 1'!A10,'Источник 1'!A10:G241, 4,0) -> Programmer | D10: =VLOOKUP('Источник 1'!A10,'Источник 1'!A10:G241,5,0) -> B01 | E10: =IF('Источник 1'!G10>0,"YES","NO") -> NO | K10: B02 | L10: =SUMIF('Источник 1'!E9:F240,'Задания 1.1'!K10,'Источник 1'!F9:F240) -> 294000 | M10: =SUMIF('Источник 1'!E10:G241, 'Задания 1.1'!K10, 'Источник 1'!G10:G241) -> 25000 | N10: =COUNTIFS(D10:D241,K10,E10:E241,"YES") -> 2
A11: 8 | B11: =_xlfn.CONCAT('Источник 1'!B11," ",'Источник 1'!C11) -> Wang Kenny | C11: =VLOOKUP('Источник 1'!A11,'Источник 1'!A11:G242, 4,0) -> Consultant | D11: =VLOOKUP('Источник 1'!A11,'Источник 1'!A11:G242,5,0) -> B01 | E11: =IF('Источник 1'!G11>0,"YES","NO") -> YES | K11: B03 | L11: =SUMIF('Источник 1'!E10:F241,'Задания 1.1'!K11,'Источник 1'!F10:F241) -> 2004000 | M11: =SUMIF('Источник 1'!E11:G242, 'Задания 1.1'!K11, 'Источник 1'!G11:G242) -> 49000 | N11: =COUNTIFS(D11:D242,K11,E11:E242,"YES") -> 12
A12: 9 | B12: =_xlfn.CONCAT('Источник 1'!B12," ",'Источник 1'!C12) -> Adams Frank | C12: =VLOOKUP('Источник 1'!A12,'Источник 1'!A12:G243, 4,0) -> Programmer | D12: =VLOOKUP('Источник 1'!A12,'Источник 1'!A12:G243,5,0) -> B01 | E12: =IF('Источник 1'!G12>0,"YES","NO") -> NO | K12: B41 | L12: =SUMIF('Источник 1'!E11:F242,'Задания 1.1'!K12,'Источник 1'!F11:F242) -> 593000 | M12: =SUMIF('Источник 1'!E12:G243, 'Задания 1.1'!K12, 'Источник 1'!G12:G243) -> 38000 | N12: =COUNTIFS(D12:D243,K12,E12:E243,"YES") -> 5
A13: 10 | B13: =_xlfn.CONCAT('Источник 1'!B13," ",'Источник 1'!C13) -> Niedzwiecki Stephanie | C13: =VLOOKUP('Источник 1'!A13,'Источник 1'!A13:G244, 4,0) -> Manager | D13: =VLOOKUP('Источник 1'!A13,'Источник 1'!A13:G244,5,0) -> B01 | E13: =IF('Источник 1'!G13>0,"YES","NO") -> YES | K13: B42 | L13: =SUMIF('Источник 1'!E12:F243,'Задания 1.1'!K13,'Источник 1'!F12:F243) -> 155000 | M13: =SUMIF('Источник 1'!E13:G244, 'Задания 1.1'!K13, 'Источник 1'!G13:G244) -> 5000 | N13: =COUNTIFS(D13:D244,K13,E13:E244,"YES") -> 1
A14: 11 | B14: =_xlfn.CONCAT('Источник 1'!B14," ",'Источник 1'!C14) -> Mallory Petee | C14: =VLOOKUP('Источник 1'!A14,'Источник 1'!A14:G245, 4,0) -> Programmer | D14: =VLOOKUP('Источник 1'!A14,'Источник 1'!A14:G245,5,0) -> B01 | E14: =IF('Источник 1'!G14>0,"YES","NO") -> YES | K14: B43 | L14: =SUMIF('Источник 1'!E13:F244,'Задания 1.1'!K14,'Источник 1'!F13:F244) -> 180000 | M14: =SUMIF('Источник 1'!E14:G245, 'Задания 1.1'!K14, 'Источник 1'!G14:G245) -> 0 | N14: =COUNTIFS(D14:D245,K14,E14:E245,"YES") -> 0
A15: 12 | B15: =_xlfn.CONCAT('Источник 1'!B15," ",'Источник 1'!C15) -> Messer Hillary | C15: =VLOOKUP('Источник 1'!A15,'Источник 1'!A15:G246, 4,0) -> Software Engineer | D15: =VLOOKUP('Источник 1'!A15,'Источник 1'!A15:G246,5,0) -> B01 | E15: =IF('Источник 1'!G15>0,"YES","NO") -> YES | K15: B44 | L15: =SUMIF('Источник 1'!E14:F245,'Задания 1.1'!K15,'Источник 1'!F14:F245) -> 304000 | M15: =SUMIF('Источник 1'!E15:G246, 'Задания 1.1'!K15, 'Источник 1'!G15:G246) -> 15000 | N15: =COUNTIFS(D15:D246,K15,E15:E246,"YES") -> 4
A16: 13 | B16: =_xlfn.CONCAT('Источник 1'!B16," ",'Источник 1'!C16) -> Fleming James | C16: =VLOOKUP('Источник 1'!A16,'Источник 1'!A16:G247, 4,0) -> Manager | D16: =VLOOKUP('Источник 1'!A16,'Источник 1'!A16:G247,5,0) -> B01 | E16: =IF('Источник 1'!G16>0,"YES","NO") -> YES | K16: B45 | L16: =SUMIF('Источник 1'!E15:F246,'Задания 1.1'!K16,'Источник 1'!F15:F246) -> 300000 | M16: =SUMIF('Источник 1'!E16:G247, 'Задания 1.1'!K16, 'Источник 1'!G16:G247) -> 15000 | N16: =COUNTIFS(D16:D247,K16,E16:E247,"YES") -> 2
... A34: 65 | B34: =_xlfn.CONCAT('Источник 1'!B34," ",'Источник 1'!C34) -> Rodes Meredith | C34: =VLOOKUP('Источник 1'!A34,'Источник 1'!A34:G265, 4,0) -> Project Manager | D34: =VLOOKUP('Источник 1'!A34,'Источник 1'!A34:G265,5,0) -> B01 | E34: =IF('Источник 1'!G34>0,"YES","NO") -> NO | K34: B81 | L34: =SUMIF('Источник 1'!E33:F264,'Задания 1.1'!K34,'Источник 1'!F33:F264) -> 170000 | M34: =SUMIF('Источник 1'!E34:G265, 'Задания 1.1'!K34, 'Источник 1'!G34:G265) -> 10000 | N34: =COUNTIFS(D34:D265,K34,E34:E265,"YES") -> 2
A35: 61 | B35: =_xlfn.CONCAT('Источник 1'!B35," ",'Источник 1'!C35) -> Evans Jan | C35: =VLOOKUP('Источник 1'!A35,'Источник 1'!A35:G266, 4,0) -> Programmer | D35: =VLOOKUP('Источник 1'!A35,'Источник 1'!A35:G266,5,0) -> B01 | E35: =IF('Источник 1'!G35>0,"YES","NO") -> YES
A36: 67 | B36: =_xlfn.CONCAT('Источник 1'!B36," ",'Источник 1'!C36) -> Adamson James | C36: =VLOOKUP('Источник 1'!A36,'Источник 1'!A36:G267, 4,0) -> Project Manager | D36: =VLOOKUP('Источник 1'!A36,'Источник 1'!A36:G267,5,0) -> B01 | E36: =IF('Источник 1'!G36>0,"YES","NO") -> YES
A37: 68 | B37: =_xlfn.CONCAT('Источник 1'!B37," ",'Источник 1'!C37) -> Brown Charles | C37: =VLOOKUP('Источник 1'!A37,'Источник 1'!A37:G268, 4,0) -> Software Developer | D37: =VLOOKUP('Источник 1'!A37,'Источник 1'!A37:G268,5,0) -> B01 | E37: =IF('Источник 1'!G37>0,"YES","NO") -> YES
A38: 69 | B38: =_xlfn.CONCAT('Источник 1'!B38," ",'Источник 1'!C38) -> Johnson Diane | C38: =VLOOKUP('Источник 1'!A38,'Источник 1'!A38:G269, 4,0) -> Programmer | D38: =VLOOKUP('Источник 1'!A38,'Источник 1'!A38:G269,5,0) -> B01 | E38: =IF('Источник 1'!G38>0,"YES","NO") -> YES | K38: Сумма Зарплата | L38: =SUM('Источник 1'!F4:F235) -> 16280000 | N38: Сумма Бонусов | O38: =SUM('Источник 1'!G4:G235) -> 580000
A39: 71 | B39: =_xlfn.CONCAT('Источник 1'!B39," ",'Источник 1'!C39) -> Horak Amy | C39: =VLOOKUP('Источник 1'!A39,'Источник 1'!A39:G270, 4,0) -> Consultant | D39: =VLOOKUP('Источник 1'!A39,'Источник 1'!A39:G270,5,0) -> B01 | E39: =IF('Источник 1'!G39>0,"YES","NO") -> YES | K39: Средняя Зарплата | L39: =AVERAGE('Источник 1'!F4:F235) -> 70172.414 | N39: Средний Бонус | O39: =AVERAGE('Источник 1'!G4:G235) -> 7073.1707
A40: 81 | B40: =_xlfn.CONCAT('Источник 1'!B40," ",'Источник 1'!C40) -> Horak Christine | C40: =VLOOKUP('Источник 1'!A40,'Источник 1'!A40:G271, 4,0) -> Programmer | D40: =VLOOKUP('Источник 1'!A40,'Источник 1'!A40:G271,5,0) -> B01 | E40: =IF('Источник 1'!G40>0,"YES","NO") -> YES | K40: Максимальная Зарплата | L40: =MAX('Источник 1'!F4:F235) -> 250000 | N40: Максимальний Бонус | O40: =MAX('Источник 1'!G4:G235) -> 50000
A41: 82 | B41: =_xlfn.CONCAT('Источник 1'!B41," ",'Источник 1'!C41) -> Gupta Amlan | C41: =VLOOKUP('Источник 1'!A41,'Источник 1'!A41:G272, 4,0) -> Programmer | D41: =VLOOKUP('Источник 1'!A41,'Источник 1'!A41:G272,5,0) -> B01 | E41: =IF('Источник 1'!G41>0,"YES","NO") -> YES | K41: Минимальная Зарплата | L41: =MIN('Источник 1'!F4:F235) -> 21000 | N41: Минимальний Бонус | O41: =MIN('Источник 1'!G4:G235) -> 500
A42: 83 | B42: =_xlfn.CONCAT('Источник 1'!B42," ",'Источник 1'!C42) -> Banister Gwen | C42: =VLOOKUP('Источник 1'!A42,'Источник 1'!A42:G273, 4,0) -> System Engineer | D42: =VLOOKUP('Источник 1'!A42,'Источник 1'!A42:G273,5,0) -> B01 | E42: =IF('Источник 1'!G42>0,"YES","NO") -> NO | K42: Сколько человек получили макс зп? | L42: =COUNTIF('Источник 1'!F4:F235,"250000") -> 3 | N42: Сколько человек получили макс Бонус? | O42: =COUNTIF('Источник 1'!G4:G235,"50000") -> 1
A43: 84 | B43: =_xlfn.CONCAT('Источник 1'!B43," ",'Источник 1'!C43) -> Adams Gwen | C43: =VLOOKUP('Источник 1'!A43,'Источник 1'!A43:G274, 4,0) -> Software Analyst | D43: =VLOOKUP('Источник 1'!A43,'Источник 1'!A43:G274,5,0) -> B01 | E43: =IF('Источник 1'!G43>0,"YES","NO") -> YES | K43: Сколько человек получили мин зп? | L43: =COUNTIF('Источник 1'!F4:F235,"21000") -> 5 | N43: Сколько человек получили мин Бонус? | O43: =COUNTIF('Источник 1'!G4:G235,"500") -> 6
A44: 85 | B44: =_xlfn.CONCAT('Источник 1'!B44," ",'Источник 1'!C44) -> Johnson Karina | C44: =VLOOKUP('Источник 1'!A44,'Источник 1'!A44:G275, 4,0) -> Consultant | D44: =VLOOKUP('Источник 1'!A44,'Источник 1'!A44:G275,5,0) -> B01 | E44: =IF('Источник 1'!G44>0,"YES","NO") -> NO
A45: 86 | B45: =_xlfn.CONCAT('Источник 1'!B45," ",'Источник 1'!C45) -> Park Karina | C45: =VLOOKUP('Источник 1'!A45,'Источник 1'!A45:G276, 4,0) -> Software Analyst | D45: =VLOOKUP('Источник 1'!A45,'Источник 1'!A45:G276,5,0) -> B01 | E45: =IF('Источник 1'!G45>0,"YES","NO") -> NO
A46: 87 | B46: =_xlfn.CONCAT('Источник 1'!B46," ",'Источник 1'!C46) -> Lee Sue | C46: =VLOOKUP('Источник 1'!A46,'Источник 1'!A46:G277, 4,0) -> Programmer | D46: =VLOOKUP('Источник 1'!A46,'Источник 1'!A46:G277,5,0) -> B01 | E46: =IF('Источник 1'!G46>0,"YES","NO") -> NO
A47: 88 | B47: =_xlfn.CONCAT('Источник 1'!B47," ",'Источник 1'!C47) -> Miller Betty | C47: =VLOOKUP('Источник 1'!A47,'Источник 1'!A47:G278, 4,0) -> Consultant | D47: =VLOOKUP('Источник 1'!A47,'Источник 1'!A47:G278,5,0) -> B01 | E47: =IF('Источник 1'!G47>0,"YES","NO") -> YES
A48: 98 | B48: =_xlfn.CONCAT('Источник 1'!B48," ",'Источник 1'!C48) -> Lee John | C48: =VLOOKUP('Источник 1'!A48,'Источник 1'!A48:G279, 4,0) -> Senior Manager | D48: =VLOOKUP('Источник 1'!A48,'Источник 1'!A48:G279,5,0) -> B92 | E48: =IF('Источник 1'!G48>0,"YES","NO") -> YES
A49: 99 | B49: =_xlfn.CONCAT('Источник 1'!B49," ",'Источник 1'!C49) -> Wang Xiu | C49: =VLOOKUP('Источник 1'!A49,'Источник 1'!A49:G280, 4,0) -> Consultant | D49: =VLOOKUP('Источник 1'!A49,'Источник 1'!A49:G280,5,0) -> B92 | E49: =IF('Источник 1'!G49>0,"YES","NO") -> YES
A50: 109 | B50: =_xlfn.CONCAT('Источник 1'!B50," ",'Источник 1'!C50) -> Lu Xue | C50: =VLOOKUP('Источник 1'!A50,'Источник 1'!A50:G281, 4,0) -> Consultant | D50: =VLOOKUP('Источник 1'!A50,'Источник 1'!A50:G281,5,0) -> B92 | E50: =IF('Источник 1'!G50>0,"YES","NO") -> YES
A51: 106 | B51: =_xlfn.CONCAT('Источник 1'!B51," ",'Источник 1'!C51) -> Lu Wei | C51: =VLOOKUP('Источник 1'!A51,'Источник 1'!A51:G282, 4,0) -> Consultant | D51: =VLOOKUP('Источник 1'!A51,'Источник 1'!A51:G282,5,0) -> B92 | E51: =IF('Источник 1'!G51>0,"YES","NO") -> NO
A52: 107 | B52: =_xlfn.CONCAT('Источник 1'!B52," ",'Источник 1'!C52) -> Krasny Igor | C52: =VLOOKUP('Источник 1'!A52,'Источник 1'!A52:G283, 4,0) -> Software Analyst | D52: =VLOOKUP('Источник 1'!A52,'Источник 1'!A52:G283,5,0) -> B92 | E52: =IF('Источник 1'!G52>0,"YES","NO") -> YES
A53: 200 | B53: =_xlfn.CONCAT('Источник 1'!B53," ",'Источник 1'!C53) -> Smidt Hans | C53: =VLOOKUP('Источник 1'!A53,'Источник 1'!A53:G284, 4,0) -> Consultant | D53: =VLOOKUP('Источник 1'!A53,'Источник 1'!A53:G284,5,0) -> B77 | E53: =IF('Источник 1'!G53>0,"YES","NO") -> YES
A54: 108 | B54: =_xlfn.CONCAT('Источник 1'!B54," ",'Источник 1'!C54) -> Mayer Inge | C54: =VLOOKUP('Источник 1'!A54,'Источник 1'!A54:G285, 4,0) -> Consultant | D54: =VLOOKUP('Источник 1'!A54,'Источник 1'!A54:G285,5,0) -> B77 | E54: =IF('Источник 1'!G54>0,"YES","NO") -> YES
A55: 206 | B55: =_xlfn.CONCAT('Источник 1'!B55," ",'Источник 1'!C55) -> Krebs Petra | C55: =VLOOKUP('Источник 1'!A55,'Источник 1'!A55:G286, 4,0) -> Consultant | D55: =VLOOKUP('Источник 1'!A55,'Источник 1'!A55:G286,5,0) -> B77 | E55: =IF('Источник 1'!G55>0,"YES","NO") -> YES
... A235: 50279 | B235: =_xlfn.CONCAT('Источник 1'!B235," ",'Источник 1'!C235) -> Gordon David | C235: =VLOOKUP('Источник 1'!A235,'Источник 1'!A235:G466, 4,0) -> Programmer | D235: =VLOOKUP('Источник 1'!A235,'Источник 1'!A235:G466,5,0) -> B01 | E235: =IF('Источник 1'!G235>0,"YES","NO") -> NO

Sheet Задания 1.2
C3: Создайте Сводную таблицу используя таблицу с Источника. Сводная таблица похожая на Рисунок 1 (ниже)
C24: СВОДНАЯ ТАБЛИЦА В СЛЕД. ЛИСТЕ-> SHEET1

Sheet Sheet1
A3: Sum of Зарплата | B3: Column Labels
A4: Row Labels | B4: B01 | C4: B02 | D4: B03 | E4: B08 | F4: B09 | G4: B17 | H4: B18 | I4: B19 | J4: B20 | K4: B41 | L4: B42 | M4: B43 | N4: B44 | O4: B45 | P4: B46 | Q4: B47 | R4: B48 | S4: B55 | T4: B61 | U4: B77 | V4: B81 | W4: B82 | X4: B83 | Y4: B84 | Z4: B85 | AA4: B86 | AB4: B87 | AC4: B88 | AD4: B89 | AE4: B90 | AF4: B92 | AG4: Grand Total
A5: Consultant | B5: 625000 | C5: 50000 | D5: 221000 | E5: 100000 | F5: 257000 | G5: 172000 | H5: 56000 | I5: 145000 | J5: 102000 | K5: 182000 | L5: 35000 | M5: 70000 | N5: 169000 | O5: 50000 | P5: 65000 | Q5: 120000 | R5: 84000 | S5: 90000 | T5: 210000 | U5: 215000 | V5: 35000 | W5: 21000 | X5: 77000 | Y5: 29000 | AA5: 96000 | AB5: 110000 | AC5: 91000 | AD5: 120000 | AE5: 85000 | AF5: 130000 | AG5: 3812000
A6: Manager | B6: 572000 | AG6: 572000
A7: Fleming | B7: 100000 | AG7: 100000
A8: Gupta | B8: 130000 | AG8: 130000
A9: Niedzwiecki | B9: 150000 | AG9: 150000
A10: Williams-Aikman | B10: 96000 | AG10: 96000
A11: Williams-Martinez | B11: 96000 | AG11: 96000
A12: Programmer | B12: 3003000 | C12: 84000 | D12: 522000 | K12: 125000 | Q12: 38000 | AG12: 3772000
A13: Project Manager | B13: 440000 | D13: 527000 | K13: 125000 | AG13: 1092000
A14: Senior Manager | B14: 172000 | C14: 160000 | D14: 195000 | E14: 110000 | F14: 130000 | G14: 120000 | H14: 250000 | I14: 90000 | J14: 100000 | K14: 161000 | L14: 120000 | M14: 110000 | N14: 80000 | O14: 250000 | P14: 150000 | Q14: 185000 | R14: 120000 | S14: 111000 | T14: 255000 | U14: 225000 | V14: 135000 | W14: 210000 | X14: 240000 | Y14: 240000 | Z14: 250000 | AA14: 110000 | AB14: 190000 | AC14: 155000 | AD14: 125000 | AE14: 145000 | AF14: 210000 | AG14: 5104000
A15: Software Analyst | B15: 338000 | D15: 196000 | N15: 55000 | AF15: 87000 | AG15: 676000
A16: Software Developer | B16: 304000 | D16: 54000 | G16: 87000 | X16: 127000 | AG16: 572000
A17: Software Engineer | B17: 184000 | AG17: 184000
A18: System Engineer | B18: 186000 | D18: 289000 | X18: 21000 | AG18: 496000
A19: Grand Total | B19: 5824000 | C19: 294000 | D19: 2004000 | E19: 210000 | F19: 387000 | G19: 379000 | H19: 306000 | I19: 235000 | J19: 202000 | K19: 593000 | L19: 155000 | M19: 180000 | N19: 304000 | O19: 300000 | P19: 215000 | Q19: 343000 | R19: 204000 | S19: 201000 | T19: 465000 | U19: 440000 | V19: 170000 | W19: 231000 | X19: 465000 | Y19: 269000 | Z19: 250000 | AA19: 206000 | AB19: 300000 | AC19: 246000 | AD19: 245000 | AE19: 230000 | AF19: 427000 | AG19: 16280000

Sheet Источник 2
A1: ID | B1: Команда | C1: Страна | D1: Имя | E1: Фамилия | F1: Вес | G1: Рост | H1: День Рождения | I1: Город | J1: Позиция | K1: Возраст | L1: Столбец1
A2: 1 | B2: Женщина | C2: Канада | D2: Meghan | E2: Agosta | F2: 74 | G2: 161 | H2: 31820 | I2: Ruthven | J2: Forward | K2: =DATEDIF(Table3[[#This Row],[День Рождения]],TODAY(),"y") -> 39 | L2: 1987
A3: 2 | B3: Женщина | C3: Канада | D3: Rebecca | E3: Johnston | F3: 74 | G3: 164 | H3: 32775 | I3: Sudbury | J3: Forward | K3: =DATEDIF(Table3[[#This Row],[День Рождения]],TODAY(),"y") -> 36 | L3: 1989
A4: 3 | B4: Женщина | C4: Канада | D4: Laura | E4: Stacey | F4: 64 | G4: 176 | H4: 34459 | I4: Kleinburg | J4: Forward | K4: =DATEDIF(Table3[[#This Row],[День Рождения]],TODAY(),"y") -> 31 | L4: 1994
A5: 4 | B5: Женщина | C5: Канада | D5: Jennifer | E5: Wakefield | F5: 68 | G5: 180 | H5: 32674 | I5: Pickering | J5: Forward | K5: =DATEDIF(Table3[[#This Row],[День Рождения]],TODAY(),"y") -> 36 | L5: 1989
A6: 5 | B6: Женщина | C6: Канада | D6: Jillian | E6: Saulnier | F6: 68 | G6: 172 | H6: 33670 | I6: Halifax | J6: Forward | K6: =DATEDIF(Table3[[#This Row],[День Рождения]],TODAY(),"y") -> 33 | L6: 1992
A7: 6 | B7: Женщина | C7: Канада | D7: Mélodie | E7: Daoust | F7: 70 | G7: 170 | H7: 33610 | I7: Valleyfield | J7: Forward | K7: =DATEDIF(Table3[[#This Row],[День Рождения]],TODAY(),"y") -> 34 | L7: 1992
A8: 7 | B8: Женщина | C8: Канада | D8: Bailey | E8: Bram | F8: 70 | G8: 167 | H8: 33121 | I8: St. Anne | J8: Forward | K8: =DATEDIF(Table3[[#This Row],[День Рождения]],TODAY(),"y") -> 35 | L8: 1990
A9: 8 | B9: Женщина | C9: Канада | D9: Brianne | E9: Jenner | F9: 72 | G9: 169 | H9: 33362 | I9: Oakville | J9: Forward | K9: =DATEDIF(Table3[[#This Row],[День Рождения]],TODAY(),"y") -> 34 | L9: 1991
A10: 9 | B10: Женщина | C10: Канада | D10: Sarah | E10: Nurse | F10: 61 | G10: 160 | H10: 34703 | I10: Hamilton | J10: Forward | K10: =DATEDIF(Table3[[#This Row],[День Рождения]],TODAY(),"y") -> 31 | L10: 1995
A11: 10 | B11: Женщина | C11: Канада | D11: Haley | E11: Irwin | F11: 72 | G11: 175 | H11: 32300 | I11: Thunder Bay | J11: Forward | K11: =DATEDIF(Table3[[#This Row],[День Рождения]],TODAY(),"y") -> 37 | L11: 1988
A12: 11 | B12: Женщина | C12: Канада | D12: Natalie | E12: Spooner | F12: 73 | G12: 172 | H12: 33163 | I12: Scarborough | J12: Forward | K12: =DATEDIF(Table3[[#This Row],[День Рождения]],TODAY(),"y") -> 35 | L12: 1990
A13: 12 | B13: Женщина | C13: Канада | D13: Emily | E13: Clark | F13: 72 | G13: 176 | H13: 35031 | I13: Saskatoon | J13: Forward | K13: =DATEDIF(Table3[[#This Row],[День Рождения]],TODAY(),"y") -> 30 | L13: 1995
... A97: 96 | B97: Мужчина | C97: США | D97: Ryan | E97: Zapolski | F97: 74 | G97: 166 | H97: 31727 | I97: Erie | J97: Goalie | K97: =DATEDIF(Table3[[#This Row],[День Рождения]],TODAY(),"y") -> 39 | L97: 1986

Sheet Задание 2.1
B3: Заполните таблицы информацией с Источника
O4: Количество
C5: Количество | O5: Канада | Q5: США
C6: Мужчины | D6: Женщины | E6: Выше 170 | F6: Ниже 170 | G6: Forward | H6: Defence | I6: Goalie | O6: Мужчины | P6: Женщины | Q6: Мужчины | R6: Женщины
B7: Канада | C7: 25 | D7: 23 | E7: 25 | F7: 23 | G7: 28 | H7: 14 | I7: 6 | N7: Forward | O7: 14 | P7: 14 | Q7: 14 | R7: 13
B8: США | C8: 25 | D8: 23 | E8: 22 | F8: 26 | G8: 27 | H8: 15 | I8: 6 | N8: Defence | O8: 8 | P8: 6 | Q8: 8 | R8: 7
N9: Goalie | O9: 3 | P9: 3 | Q9: 3 | R9: 3
C12: Средний возраст | E12: Средний рост | G12: Средний вес
C13: Мужчины | D13: Женщины | E13: Мужчины | F13: Женщины | G13: Мужчины | H13: Женщины
B14: Канада | C14: 39 | D14: 35 | E14: 169 | F14: 170 | G14: 67 | H14: 68
B15: США | C15: 38 | D15: 33 | E15: 168 | F15: 170 | G15: 68 | H15: 68
B18: Рост | C18: (All)
B20: Count of ID | C20: Column Labels | I20: Column Labels
B21: Row Labels | C21: Мужчина | D21: Женщина | E21: Grand Total | I21: Мужчина | M21: Женщина | Q21: Total Count of ID | R21: Total Average of Возраст | S21: Total Average of Рост | T21: Total Average of Вес
B22: Канада | C22: 25 | D22: 23 | E22: 48 | H22: Row Labels | I22: Count of ID | J22: Average of Возраст | K22: Average of Рост | L22: Average of Вес | M22: Count of ID | N22: Average of Возраст | O22: Average of Рост | P22: Average of Вес
B23: Defence | C23: 8 | D23: 6 | E23: 14 | H23: Канада | I23: 25 | J23: 38.56 | K23: 168.52 | L23: 66.52 | M23: 23 | N23: 34.565217 | O23: 170.47826 | P23: 68.217391 | Q23: 48 | R23: 36.645833 | S23: 169.45833 | T23: 67.333333
B24: Forward | C24: 14 | D24: 14 | E24: 28 | H24: США | I24: 25 | J24: 37.6 | K24: 168.24 | L24: 68.28 | M24: 23 | N24: 32.652174 | O24: 170 | P24: 67.782609 | Q24: 48 | R24: 35.229167 | S24: 169.08333 | T24: 68.041667
B25: Goalie | C25: 3 | D25: 3 | E25: 6 | H25: Grand Total | I25: 50 | J25: 38.08 | K25: 168.38 | L25: 67.4 | M25: 46 | N25: 33.608696 | O25: 170.23913 | P25: 68 | Q25: 96 | R25: 35.9375 | S25: 169.27083 | T25: 67.6875
B26: США | C26: 25 | D26: 23 | E26: 48
B27: Defence | C27: 8 | D27: 7 | E27: 15
B28: Forward | C28: 14 | D28: 13 | E28: 27
B29: Goalie | C29: 3 | D29: 3 | E29: 6
B30: Grand Total | C30: 50 | D30: 46 | E30: 96
H31: Count of Позиция | I31: Column Labels
I32: Канада | K32: Канада Total | L32: США | N32: США Total | O32: Grand Total
H33: Row Labels | I33: Женщина | J33: Мужчина | L33: Женщина | M33: Мужчина
H34: Forward | I34: 14 | J34: 14 | K34: 28 | L34: 13 | M34: 14 | N34: 27 | O34: 55
H35: Goalie | I35: 3 | J35: 3 | K35: 6 | L35: 3 | M35: 3 | N35: 6 | O35: 12
H36: Defence | I36: 6 | J36: 8 | K36: 14 | L36: 7 | M36: 8 | N36: 15 | O36: 29
H37: Grand Total | I37: 23 | J37: 25 | K37: 48 | L37: 23 | M37: 25 | N37: 48 | O37: 96

Sheet Задание Графики
C2: Задание на креатив: Создайте 4 разных графика, используя данные с Источника 1 и Источник 2 (не забудьте добавить Наименование, Легенды и тд и тп)
B4: Row Labels | C4: Count of ID | T4: Row Labels | U4: Count of ID
B5: Consultant | C5: 81 | T5: Defence | U5: 29
B6: Manager | C6: 5 | T6: Forward | U6: 55
B7: Programmer | C7: 64 | T7: Goalie | U7: 12
B8: Project Manager | C8: 12 | T8: Grand Total | U8: 96
B9: Senior Manager | C9: 32
B10: Software Analyst | C10: 11
B11: Software Developer | C11: 14
B12: Software Engineer | C12: 3
B13: System Engineer | C13: 10
B14: Grand Total | C14: 232
B30: Business-unit | C30: Average salary | T30: Count of ID | U30: Column Labels
B31: B01 | C31: =AVERAGEIF('Источник 1'!E4:F235,'Задание Графики'!B31,'Источник 1'!F4:F235) -> 72800 | T31: Row Labels | U31: 27 | V31: 28 | W31: 29 | X31: 30 | Y31: 31 | Z31: 32 | AA31: 33 | AB31: 34 | AC31: 35 | AD31: 36 | AE31: 37 | AF31: 38 | AG31: 39 | AH31: 40 | AI31: 41 | AJ31: 42 | AK31: 43 | AL31: 44 | AM31: 45 | AN31: 47 | AO31: Grand Total
B32: B02 | C32: =AVERAGEIF('Источник 1'!E10:F241,'Задание Графики'!B37,'Источник 1'!F10:F241) -> 153000 | T32: Женщина | U32: 1 | V32: 1 | W32: 1 | X32: 5 | Y32: 6 | Z32: 5 | AA32: 3 | AB32: 6 | AC32: 4 | AD32: 6 | AE32: 2 | AF32: 3 | AG32: 2 | AI32: 1 | AO32: 46
B33: B03 | C33: =AVERAGEIF('Источник 1'!E11:F242,'Задание Графики'!B38,'Источник 1'!F11:F242) -> 47000 | T33: Мужчина | V33: 1 | W33: 3 | AA33: 1 | AB33: 3 | AC33: 4 | AD33: 2 | AE33: 4 | AF33: 7 | AG33: 8 | AH33: 6 | AI33: 2 | AJ33: 2 | AK33: 3 | AL33: 1 | AM33: 2 | AN33: 1 | AO33: 50
B34: B08 | C34: =AVERAGEIF('Источник 1'!E22:F253,'Задание Графики'!B49,'Источник 1'!F22:F253) -> 93000 | T34: Grand Total | U34: 1 | V34: 2 | W34: 4 | X34: 5 | Y34: 6 | Z34: 5 | AA34: 4 | AB34: 9 | AC34: 8 | AD34: 8 | AE34: 6 | AF34: 10 | AG34: 10 | AH34: 6 | AI34: 3 | AJ34: 2 | AK34: 3 | AL34: 1 | AM34: 2 | AN34: 1 | AO34: 96
B35: B09 | C35: =AVERAGEIF('Источник 1'!E23:F254,'Задание Графики'!B50,'Источник 1'!F23:F254) -> 110000
B36: B17 | C36: =AVERAGEIF('Источник 1'!E20:F251,'Задание Графики'!B47,'Источник 1'!F20:F251) -> 68000 | U36: 27 | V36: 28 | W36: 29 | X36: 30 | Y36: 31 | Z36: 32 | AA36: 33 | AB36: 34 | AC36: 35 | AD36: 36 | AE36: 37 | AF36: 38 | AG36: 39 | AH36: 40 | AI36: 41 | AJ36: 42 | AK36: 43 | AL36: 44 | AM36: 45 | AN36: 47
B37: B18 | C37: =AVERAGEIF('Источник 1'!E7:F238,'Задание Графики'!B34,'Источник 1'!F7:F238) -> 70000 | T37: Woman | U37: 1 | V37: 1 | W37: 1 | X37: 5 | Y37: 6 | Z37: 5 | AA37: 3 | AB37: 6 | AC37: 4 | AD37: 6 | AE37: 2 | AF37: 3 | AG37: 2 | AI37: 1
B38: B19 | C38: =AVERAGEIF('Источник 1'!E8:F239,'Задание Графики'!B35,'Источник 1'!F8:F239) -> 55285.714 | T38: Man | V38: 1 | W38: 3 | AA38: 1 | AB38: 3 | AC38: 4 | AD38: 2 | AE38: 4 | AF38: 7 | AG38: 8 | AH38: 6 | AI38: 2 | AJ38: 2 | AK38: 3 | AL38: 1 | AM38: 2 | AN38: 1
B39: B20 | C39: =AVERAGEIF('Источник 1'!E9:F240,'Задание Графики'!B36,'Источник 1'!F9:F240) -> 37900
B40: B41 | C40: =AVERAGEIF('Источник 1'!E12:F243,'Задание Графики'!B39,'Источник 1'!F12:F243) -> 50500
B41: B42 | C41: =AVERAGEIF('Источник 1'!E13:F244,'Задание Графики'!B40,'Источник 1'!F13:F244) -> 74125
B42: B43 | C42: =AVERAGEIF('Источник 1'!E14:F245,'Задание Графики'!B41,'Источник 1'!F14:F245) -> 77500
B43: B44 | C43: =AVERAGEIF('Источник 1'!E15:F246,'Задание Графики'!B42,'Источник 1'!F15:F246) -> 60000
B44: B45 | C44: =AVERAGEIF('Источник 1'!E16:F247,'Задание Графики'!B43,'Источник 1'!F16:F247) -> 43428.571
B45: B46 | C45: =AVERAGEIF('Источник 1'!E17:F248,'Задание Графики'!B44,'Источник 1'!F17:F248) -> 150000
B46: B47 | C46: =AVERAGEIF('Источник 1'!E18:F249,'Задание Графики'!B45,'Источник 1'!F18:F249) -> 107500
B47: B48 | C47: =AVERAGEIF('Источник 1'!E19:F250,'Задание Графики'!B46,'Источник 1'!F19:F250) -> 68600
B48: B55 | C48: =AVERAGEIF('Источник 1'!E21:F252,'Задание Графики'!B48,'Источник 1'!F21:F252) -> 67000
B49: B61 | C49: =AVERAGEIF('Источник 1'!E24:F255,'Задание Графики'!B51,'Источник 1'!F24:F255) -> 85000
B50: B77 | C50: =AVERAGEIF('Источник 1'!E6:F237,'Задание Графики'!B33,'Источник 1'!F6:F237) -> 52736.842
B51: B81 | C51: =AVERAGEIF('Источник 1'!E34:F265,'Задание Графики'!B61,'Источник 1'!F34:F265) -> 85400
B52: B82 | C52: =AVERAGEIF('Источник 1'!E33:F264,'Задание Графики'!B60,'Источник 1'!F33:F264) -> 76666.667
B53: B83 | C53: =AVERAGEIF('Источник 1'!E32:F263,'Задание Графики'!B59,'Источник 1'!F32:F263) -> 81666.667
B54: B84 | C54: =AVERAGEIF('Источник 1'!E31:F262,'Задание Графики'!B58,'Источник 1'!F31:F262) -> 123000
B55: B85 | C55: =AVERAGEIF('Источник 1'!E30:F261,'Задание Графики'!B57,'Источник 1'!F30:F261) -> 150000
B56: B86 | C56: =AVERAGEIF('Источник 1'!E29:F260,'Задание Графики'!B56,'Источник 1'!F29:F260) -> 68666.667
B57: B87 | C57: =AVERAGEIF('Источник 1'!E28:F259,'Задание Графики'!B55,'Источник 1'!F28:F259) -> 250000
...
